Workbook

Sheet Sales_Data
A1: Order_ID | B1: Order_Date | C1: Customer_Name | D1: City | E1: State | F1: Product | G1: Category | H1: Quantity | I1: Unit_Price | J1: Discount_% | K1: Gross_Sales | L1: Discount_Amount | M1: Net_Sales | N1: Sales_Channel | O1: Payment_Method | P1: Order_Status | Q1: Salesperson | R1: Sales Profmance | S1: Sales_Classification
A2: ORD0051 | B2: 46194 | C2: Karan Singh | D2: Agra | E2: Uttar Pradesh | F2: Notebook | G2: Stationery | H2: 4 | I2: 160 | J2: 0.1 | K2: 640 | L2: 64 | M2: 576 | N2: Mobile App | O2: Credit Card | P2: Delivered | Q2: Esha | R2: =IF(M2>=50000,"High","Low") -> Low | S2: =IF(M2>=50000,"High",IF(M2>=25000,"Medium","Low")) -> Low
A3: ORD0064 | B3: 46092 | C3: Rohan Yadav | D3: Noida | E3: Uttar Pradesh | F3: Notebook | G3: Stationery | H3: 5 | I3: 170 | J3: 0.15 | K3: 850 | L3: 127.5 | M3: 722.5 | N3: Marketplace | O3: Credit Card | P3: Delivered | Q3: Chetan | R3: =IF(M3>=50000,"High","Low") -> Low | S3: =IF(M3>=50000,"High",IF(M3>=25000,"Medium","Low")) -> Low
A4: ORD0012 | B4: 46151 | C4: Mohit Yadav | D4: Agra | E4: Uttar Pradesh | F4: Notebook | G4: Stationery | H4: 2 | I4: 180 | J4: 0.1 | K4: 360 | L4: 36 | M4: 324 | N4: Marketplace | O4: Debit Card | P4: Delivered | Q4: Esha | R4: =IF(M4>=50000,"High","Low") -> Low | S4: =IF(M4>=50000,"High",IF(M4>=25000,"Medium","Low")) -> Low
A5: ORD0089 | B5: 46136 | C5: Pooja Sharma | D5: Lucknow | E5: Uttar Pradesh | F5: Notebook | G5: Stationery | H5: 1 | I5: 190 | J5: 0 | K5: 190 | L5: 0 | M5: 190 | N5: Website | O5: Debit Card | P5: Delivered | Q5: Aman | R5: =IF(M5>=50000,"High","Low") -> Low | S5: =IF(M5>=50000,"High",IF(M5>=25000,"Medium","Low")) -> Low
A6: ORD0039 | B6: 46182 | C6: Priya Gupta | D6: Noida | E6: Uttar Pradesh | F6: Notebook | G6: Stationery | H6: 1 | I6: 200 | J6: 0.1 | K6: 200 | L6: 20 | M6: 180 | N6: Marketplace | O6: Debit Card | P6: Delivered | Q6: Deepak | R6: =IF(M6>=50000,"High","Low") -> Low | S6: =IF(M6>=50000,"High",IF(M6>=25000,"Medium","Low")) -> Low
A7: ORD0006 | B7: 46076 | C7: Ananya Agarwal | D7: Agra | E7: Uttar Pradesh | F7: Pen Set | G7: Stationery | H7: 3 | I7: 230 | J7: 0.1 | K7: 690 | L7: 69 | M7: 621 | N7: Marketplace | O7: Credit Card | P7: Delivered | Q7: Esha | R7: =IF(M7>=50000,"High","Low") -> Low | S7: =IF(M7>=50000,"High",IF(M7>=25000,"Medium","Low")) -> Low
A8: ORD0021 | B8: 46237 | C8: Ananya Verma | D8: Lucknow | E8: Uttar Pradesh | F8: Pen Set | G8: Stationery | H8: 5 | I8: 230 | J8: 0.2 | K8: 1150 | L8: 230 | M8: 920 | N8: Website | O8: Net Banking | P8: Delivered | Q8: Deepak | R8: =IF(M8>=50000,"High","Low") -> Low | S8: =IF(M8>=50000,"High",IF(M8>=25000,"Medium","Low")) -> Low
A9: ORD0059 | B9: 46189 | C9: Kavya Kumar | D9: Noida | E9: Uttar Pradesh | F9: Pen Set | G9: Stationery | H9: 2 | I9: 250 | J9: 0.2 | K9: 500 | L9: 100 | M9: 400 | N9: Mobile App | O9: Net Banking | P9: Delivered | Q9: Esha | R9: =IF(M9>=50000,"High","Low") -> Low | S9: =IF(M9>=50000,"High",IF(M9>=25000,"Medium","Low")) -> Low
A10: ORD0074 | B10: 46202 | C10: Vikas Tiwari | D10: Agra | E10: Uttar Pradesh | F10: Pen Set | G10: Stationery | H10: 1 | I10: 250 | J10: 0.1 | K10: 250 | L10: 25 | M10: 225 | N10: Marketplace | O10: Net Banking | P10: Delivered | Q10: Deepak | R10: =IF(M10>=50000,"High","Low") -> Low | S10: =IF(M10>=50000,"High",IF(M10>=25000,"Medium","Low")) -> Low
A11: ORD0023 | B11: 46037 | C11: Kavya Sharma | D11: Patna | E11: Bihar | F11: Calculator | G11: Stationery | H11: 2 | I11: 520 | J11: 0.05 | K11: 1040 | L11: 52 | M11: 988 | N11: Marketplace | O11: Debit Card | P11: Delivered | Q11: Aman | R11: =IF(M11>=50000,"High","Low") -> Low | S11: =IF(M11>=50000,"High",IF(M11>=25000,"Medium","Low")) -> Low
A12: ORD0035 | B12: 46112 | C12: Rohan Verma | D12: Prayagraj | E12: Uttar Pradesh | F12: Calculator | G12: Stationery | H12: 2 | I12: 520 | J12: 0.15 | K12: 1040 | L12: 156 | M12: 884 | N12: Website | O12: Credit Card | P12: Delivered | Q12: Deepak | R12: =IF(M12>=50000,"High","Low") -> Low | S12: =IF(M12>=50000,"High",IF(M12>=25000,"Medium","Low")) -> Low
A13: ORD0093 | B13: 46114 | C13: Pooja Sharma | D13: Delhi | E13: Delhi | F13: Calculator | G13: Stationery | H13: 1 | I13: 520 | J13: 0.2 | K13: 520 | L13: 104 | M13: 416 | N13: Marketplace | O13: Net Banking | P13: Delivered | Q13: Chetan | R13: =IF(M13>=50000,"High","Low") -> Low | S13: =IF(M13>=50000,"High",IF(M13>=25000,"Medium","Low")) -> Low
... A101: ORD0062 | B101: 46084 | C101: Nisha Tiwari | D101: Patna | E101: Bihar | F101: Laptop | G101: Electronics | H101: 5 | I101: 59930 | J101: 0 | K101: 299650 | L101: 0 | M101: 299650 | N101: Website | O101: Net Banking | P101: Delivered | Q101: Deepak | R101: =IF(M101>=50000,"High","Low") -> High | S101: =IF(M101>=50000,"High",IF(M101>=25000,"Medium","Low")) -> High
H102: =SUM(Sales_Data!H2:H101) -> 276
A103: Total Order | H103: =SUM(Sales_Data!H2:H101) -> 276 | K103: =SUM(Sales_Data!K2:K101) -> 2955590 | M103: =SUM(Sales_Data!M2:M101) -> 2764145 | P103: =COUNTIF(P2:P101,"Delivered") -> 87
A104: =COUNT(A2:A101) -> 0 | C104: Delhi & Electronics | D104: =COUNTIFS(Sales_Data!E2:E101,"Delhi",Sales_Data!G2:G101,"Ekectronics") -> 0 | L104: average | M104: =AVERAGE(Sales_Data!M2:M101) -> 27641.45
C105: Delhi & Furniture | D105: =COUNTIFS(Sales_Data!E2:E101,"Delhi",Sales_Data!G2:G101,"Furniture") -> 1 | L105: Highest | M105: =MAX(Sales_Data!M2:M101) -> 299650
C106: Delhi & Accessories | D106: =COUNTIFS(Sales_Data!E2:E101,"Delhi",Sales_Data!G2:G101,"Accessories") -> 5 | F106: Marketplace | G106: =COUNTIF(N2:N101,"Marketplace") -> 32 | L106: Lowest | M106: =MIN(Sales_Data!M2:M101) -> 180
B107: Utter Pradesh & Electronics | D107: =COUNTIFS(Sales_Data!E2:E101,"Utter Pradesh",Sales_Data!G2:G101,"Electronics") -> 0 | F107: Website | G107: =COUNTIF(N2:N101,"Website") -> 34
B108: Utter Pradesh & Furniture | D108: =COUNTIFS(Sales_Data!E2:E101,"Utter Pradesh",Sales_Data!G2:G101,"Furniture") -> 0 | F108: Mobile App | G108: =COUNTIF(N2:N101,"Mobile App") -> 34
B109: Utter Pradesh & Accessories | D109: =COUNTIFS(Sales_Data!E2:E101,"Utter Pradesh",Sales_Data!G2:G101,"Accessories") -> 0 | F109: Delivered & Website | H109: =COUNTIFS(Sales_Data!P2:P101,"Delivered",Sales_Data!N2:N101,"Website") -> 31 | K109: =C2& " - "&D2 -> Karan Singh - Agra
F110: Shipped & Mobile App | H110: =COUNTIFS(Sales_Data!P2:P101,"Shipped",Sales_Data!N2:N101,"Mobile App") -> 2 | K110: =C4& " " &D3 -> Mohit Yadav Noida
E113: Order Above50000 | F113: =COUNTIF(Sales_Data!M2:M101,">=50000") -> 12
E114: Order B/W Range 10000 & 40000 | F114: =COUNTIFS(Sales_Data!M2:M101,">=10000",Sales_Data!M2:M101,"<=40000") -> 22
E115: 10000 & 20000 | F115: =COUNTIFS(Sales_Data!M2:M101,">=10000",Sales_Data!M2:M101,"<=20000") -> 10
E116: 10000 & 50000 | F116: =COUNTIFS(Sales_Data!M2:M101,">=10000",Sales_Data!M2:M101,"<=50000") -> 27
E118: Electronics total sales | F118: =SUMIF(Sales_Data!G2:G101,"Electronics",Sales_Data!M2:M101) -> 2458807
E119: Furniture | F119: =SUMIF(Sales_Data!G2:G101,"Furniture",Sales_Data!M2:M101) -> 222850
E120: Accessirues | F120: =SUMIF(Sales_Data!G2:G101,"Accessories",Sales_Data!M2:M101) -> 74509.5
E121: Stationery | F121: =SUMIF(Sales_Data!G2:G101,"Stationery",Sales_Data!M2:M101) -> 7978.5

Sheet Exercises

Sheet Product_Lookup

Sheet PivotChart
B2: Row Labels | C2: Sum of Gross_Sales | G2: Row Labels | H2: Sum of Net_Sales | K2: Row Labels | L2: Sum of Discount_% | M2: Sum of Gross_Sales | Q2: Row Labels | R2: Sum of Net_Sales | S2: Sum of Gross_Sales
B3: Aarav Agarwal | C3: 53320 | G3: Aditya Sharma | H3: 1584 | K3: Delhi | L3: 1.6 | M3: 159620 | Q3: Backpack | R3: 9964.5 | S3: 10730
B4: Aarav Patel | C4: 6600 | G4: Aditya Singh | H4: 5420 | K4: Kanpur | L4: 0.7 | M4: 180640 | Q4: Calculator | R4: 3820 | S4: 4250
B5: Aditya Agarwal | C5: 44360 | G5: Aditya Verma | H5: 3744 | K5: Lucknow | L5: 1.05 | M5: 246580 | Q5: Desk | R5: 85241 | S5: 96100
B6: Aditya Gupta | C6: 9330 | G6: Aditya Yadav | H6: 1782 | K6: Noida | L6: 1.1 | M6: 330920 | Q6: External HDD | R6: 50473.5 | S6: 60910
B7: Aditya Mishra | C7: 1420 | G7: Amit Tiwari | H7: 23698 | K7: Prayagraj | L7: 1.05 | M7: 312690 | Q7: Headphones | R7: 15173 | S7: 15980
B8: Aditya Sharma | C8: 1760 | G8: Amit Yadav | H8: 136988 | K8: Varanasi | L8: 0.6 | M8: 38070 | Q8: Keyboard | R8: 15803 | S8: 17830
B9: Aditya Singh | C9: 5750 | G9: Grand Total | H9: 173216 | K9: Grand Total | L9: 6.1 | M9: 1268520 | Q9: Laptop | R9: 1559470 | S9: 1634710
B10: Grand Total | C10: 122540 | Q10: Monitor | R10: 193815.5 | S10: 206370
Q11: Mouse | R11: 7855 | S11: 8440
Q12: Notebook | R12: 1992.5 | S12: 2240
Q13: Office Chair | R13: 137609 | S13: 141100
Q14: Pen Set | R14: 2166 | S14: 2590
Q15: Power Bank | R15: 25176 | S15: 27710
Q16: Printer | R16: 65711.5 | S16: 71620
Q17: Smartphone | R17: 204216 | S17: 222250
Q18: Smartwatch | R18: 76731 | S18: 85070
Q19: Speaker | R19: 38074.5 | S19: 45440
Q20: Tablet | R20: 210045.5 | S20: 236310
Q21: USB Drive | R21: 15711 | S21: 17600
Q22: Webcam | R22: 45096.5 | S22: 48340
Q23: Grand Total | R23: 2764145 | S23: 2955590
H26: Row Labels | I26: Sum of Quantity | J26: Sum of Unit_Price | K26: Sum of Discount_% | L26: Sum of Gross_Sales | M26: Sum of Discount_Amount | N26: Sum of Net_Sales
H27: Amit Yadav | I27: 4 | J27: 4920 | K27: 0.05 | L27: 19680 | M27: 984 | N27: 18696
B28: Row Labels | C28: Sum of Net_Sales | H28: Delhi | I28: 4 | J28: 4920 | K28: 0.05 | L28: 19680 | M28: 984 | N28: 18696
B29: Jan | C29: 525982.5 | H29: Delhi | I29: 4 | J29: 4920 | K29: 0.05 | L29: 19680 | M29: 984 | N29: 18696
B30: Feb | C30: 203187 | H30: Smartwatch | I30: 4 | J30: 4920 | K30: 0.05 | L30: 19680 | M30: 984 | N30: 18696
B31: Mar | C31: 569955 | H31: Electronics | I31: 4 | J31: 4920 | K31: 0.05 | L31: 19680 | M31: 984 | N31: 18696
B32: Apr | C32: 187843.5 | H32: Mobile App | I32: 4 | J32: 4920 | K32: 0.05 | L32: 19680 | M32: 984 | N32: 18696
B33: May | C33: 431359 | H33: UPI | I33: 4 | J33: 4920 | K33: 0.05 | L33: 19680 | M33: 984 | N33: 18696
B34: Jun | C34: 123646.5 | H34: Returned | I34: 4 | J34: 4920 | K34: 0.05 | L34: 19680 | M34: 984 | N34: 18696
B35: Jul | C35: 350634.5 | H35: Esha | I35: 4 | J35: 4920 | K35: 0.05 | L35: 19680 | M35: 984 | N35: 18696
B36: Aug | C36: 371537 | H36: Low | I36: 4 | J36: 4920 | K36: 0.05 | L36: 19680 | M36: 984 | N36: 18696
B37: Grand Total | C37: 2764145 | H37: Low | I37: 4 | J37: 4920 | K37: 0.05 | L37: 19680 | M37: 984 | N37: 18696
H38: 09-May
H39: May | I39: 4 | J39: 4920 | K39: 0.05 | L39: 19680 | M39: 984 | N39: 18696
H40: Grand Total | I40: 4 | J40: 4920 | K40: 0.05 | L40: 19680 | M40: 984 | N40: 18696
C57: Sates | D57: Sales
C58: Uttar Pradesh | D58: =SUMIF(Sales_Data!E:E,C58,Sales_Data!M:M) -> 1280588
C59: Delhi | D59: =SUMIF(Sales_Data!E:E,C59,Sales_Data!M:M) -> 134788.5
...

Sheet Sheet2
A1: Excel_Practice_Exercises
A2: Calculate Total Net Sales, Average Order Value, Maximum and Minimum Net Sales.
A3: Use SUMIF/SUMIFS to calculate sales by category, city, salesperson and status.
A4: Use COUNTIF/COUNTIFS to count orders by status, channel and payment method.
A5: Use IF/IFS to create a Sales_Performance column based on Net_Sales.
A6: Use XLOOKUP/VLOOKUP to retrieve product category and price from a separate lookup table.
A7: Use LEFT, RIGHT, MID, LEN, TRIM, UPPER/LOWER/PROPER on Customer_Name and Order_ID.
A8: Extract Month, Quarter, Day and Weekday from Order_Date.
A9: Create a PivotTable: Category vs Net Sales and Quantity.
A10: Create a PivotTable: City vs Salesperson vs Net Sales.
A11: Create a PivotChart showing monthly Net Sales.
A12: Identify top 5 products and top 5 customers by Net Sales.
... A15: Create a dashboard with KPIs, slicers and charts.

Sheet Sheet3
